{
 "cells": [
  {
   "cell_type": "code",
   "execution_count": 1,
   "id": "fc071a0d",
   "metadata": {},
   "outputs": [],
   "source": [
    "from deeptrace import *\n",
    "stack = BrainStack(channel_folders=['../../sampledata/210723_NAc326F_488_s3_0_8x_13-31-25/',\n",
    "                   '../../sampledata/210723_NAc326F_640_s3_0_8x_11-50-51/'])\n",
    "trailmap_channel = 1\n",
    "stack.set_active_channels([trailmap_channel])\n"
   ]
  },
  {
   "cell_type": "code",
   "execution_count": 2,
   "id": "f0b1435a",
   "metadata": {},
   "outputs": [
    {
     "data": {
      "application/vnd.jupyter.widget-view+json": {
       "model_id": "c3bd9714782740618cfa1149d636ed2a",
       "version_major": 2,
       "version_minor": 0
      },
      "text/plain": [
       "0it [00:00, ?it/s]"
      ]
     },
     "metadata": {},
     "output_type": "display_data"
    },
    {
     "name": "stdout",
     "output_type": "stream",
     "text": [
      "Loading TRAILMAP network and model.\n",
      "Using model weight denardo_trapmodel4.hdf5\n"
     ]
    }
   ],
   "source": [
    "\n",
    "files = stack.channel_files[trailmap_channel]\n",
    "from tqdm.notebook import tqdm\n",
    "pbar = tqdm()\n",
    "models = trailmap_list_models()\n",
    "model_path = models[4]\n",
    "trailmap_segment_tif_files(model_path, files,pbar = pbar)"
   ]
  },
  {
   "cell_type": "code",
   "execution_count": 3,
   "id": "5da193f9",
   "metadata": {},
   "outputs": [],
   "source": [
    "stack = BrainStack(channel_folders=['../../sampledata/denardo_trapmodel4_seg-210723_NAc326F_640_s3_0_8x_11-50-51'])\n",
    "stack.downsample(pbar = pbar)"
   ]
  },
  {
   "cell_type": "code",
   "execution_count": 4,
   "id": "7f2c656f",
   "metadata": {},
   "outputs": [
    {
     "name": "stdout",
     "output_type": "stream",
     "text": [
      "Downsampling channel 0.\n"
     ]
    }
   ],
   "source": [
    "# now use 3 colors to visualize\n",
    "stack = BrainStack(channel_folders=['../../sampledata/denardo_trapmodel4_seg-210723_NAc326F_640_s3_0_8x_11-50-51',\n",
    "                                   '../../sampledata/210723_NAc326F_488_s3_0_8x_13-31-25/',\n",
    "                                    '../../sampledata/210723_NAc326F_640_s3_0_8x_11-50-51/'],downsample = True)\n"
   ]
  },
  {
   "cell_type": "code",
   "execution_count": null,
   "id": "b42772ee",
   "metadata": {},
   "outputs": [
    {
     "name": "stderr",
     "output_type": "stream",
     "text": [
      "ERROR:root:Internal Python error in the inspect module.\n",
      "Below is the traceback from this internal error.\n",
      "\n",
      "ERROR:root:Internal Python error in the inspect module.\n",
      "Below is the traceback from this internal error.\n",
      "\n",
      "ERROR:root:Internal Python error in the inspect module.\n",
      "Below is the traceback from this internal error.\n",
      "\n"
     ]
    },
    {
     "name": "stdout",
     "output_type": "stream",
     "text": [
      "Traceback (most recent call last):\n",
      "  File \"C:\\users\\Milner\\anaconda3\\envs\\trailmap_env\\lib\\site-packages\\IPython\\core\\interactiveshell.py\", line 3457, in run_code\n",
      "    exec(code_obj, self.user_global_ns, self.user_ns)\n",
      "  File \"C:\\Users\\Milner\\AppData\\Local\\Temp\\ipykernel_16592\\3907816014.py\", line 5, in <module>\n",
      "    import pylab as plt\n",
      "ModuleNotFoundError: No module named 'pylab'\n",
      "\n",
      "During handling of the above exception, another exception occurred:\n",
      "\n",
      "Traceback (most recent call last):\n",
      "  File \"C:\\users\\Milner\\anaconda3\\envs\\trailmap_env\\lib\\site-packages\\IPython\\core\\interactiveshell.py\", line 2077, in showtraceback\n",
      "    stb = value._render_traceback_()\n",
      "AttributeError: 'ModuleNotFoundError' object has no attribute '_render_traceback_'\n",
      "\n",
      "During handling of the above exception, another exception occurred:\n",
      "\n",
      "Traceback (most recent call last):\n",
      "  File \"C:\\users\\Milner\\anaconda3\\envs\\trailmap_env\\lib\\site-packages\\IPython\\core\\ultratb.py\", line 1101, in get_records\n",
      "    return _fixed_getinnerframes(etb, number_of_lines_of_context, tb_offset)\n",
      "  File \"C:\\users\\Milner\\anaconda3\\envs\\trailmap_env\\lib\\site-packages\\IPython\\core\\ultratb.py\", line 248, in wrapped\n",
      "    return f(*args, **kwargs)\n",
      "  File \"C:\\users\\Milner\\anaconda3\\envs\\trailmap_env\\lib\\site-packages\\IPython\\core\\ultratb.py\", line 281, in _fixed_getinnerframes\n",
      "    records = fix_frame_records_filenames(inspect.getinnerframes(etb, context))\n",
      "  File \"C:\\users\\Milner\\anaconda3\\envs\\trailmap_env\\lib\\inspect.py\", line 1502, in getinnerframes\n",
      "    frameinfo = (tb.tb_frame,) + getframeinfo(tb, context)\n",
      "  File \"C:\\users\\Milner\\anaconda3\\envs\\trailmap_env\\lib\\inspect.py\", line 1460, in getframeinfo\n",
      "    filename = getsourcefile(frame) or getfile(frame)\n",
      "  File \"C:\\users\\Milner\\anaconda3\\envs\\trailmap_env\\lib\\inspect.py\", line 696, in getsourcefile\n",
      "    if getattr(getmodule(object, filename), '__loader__', None) is not None:\n",
      "  File \"C:\\users\\Milner\\anaconda3\\envs\\trailmap_env\\lib\\inspect.py\", line 733, in getmodule\n",
      "    if ismodule(module) and hasattr(module, '__file__'):\n",
      "  File \"C:\\users\\Milner\\anaconda3\\envs\\trailmap_env\\lib\\site-packages\\tensorflow\\__init__.py\", line 50, in __getattr__\n",
      "    module = self._load()\n",
      "  File \"C:\\users\\Milner\\anaconda3\\envs\\trailmap_env\\lib\\site-packages\\tensorflow\\__init__.py\", line 44, in _load\n",
      "    module = _importlib.import_module(self.__name__)\n",
      "  File \"C:\\users\\Milner\\anaconda3\\envs\\trailmap_env\\lib\\importlib\\__init__.py\", line 127, in import_module\n",
      "    return _bootstrap._gcd_import(name[level:], package, level)\n",
      "  File \"<frozen importlib._bootstrap>\", line 1006, in _gcd_import\n",
      "  File \"<frozen importlib._bootstrap>\", line 983, in _find_and_load\n",
      "  File \"<frozen importlib._bootstrap>\", line 965, in _find_and_load_unlocked\n",
      "ModuleNotFoundError: No module named 'tensorflow_core.estimator'\n",
      "Traceback (most recent call last):\n",
      "  File \"C:\\users\\Milner\\anaconda3\\envs\\trailmap_env\\lib\\site-packages\\IPython\\core\\interactiveshell.py\", line 3457, in run_code\n",
      "    exec(code_obj, self.user_global_ns, self.user_ns)\n",
      "  File \"C:\\Users\\Milner\\AppData\\Local\\Temp\\ipykernel_16592\\3907816014.py\", line 5, in <module>\n",
      "    import pylab as plt\n",
      "ModuleNotFoundError: No module named 'pylab'\n",
      "\n",
      "During handling of the above exception, another exception occurred:\n",
      "\n",
      "Traceback (most recent call last):\n",
      "  File \"C:\\users\\Milner\\anaconda3\\envs\\trailmap_env\\lib\\site-packages\\IPython\\core\\interactiveshell.py\", line 2077, in showtraceback\n",
      "    stb = value._render_traceback_()\n",
      "AttributeError: 'ModuleNotFoundError' object has no attribute '_render_traceback_'\n",
      "\n",
      "During handling of the above exception, another exception occurred:\n",
      "\n",
      "Traceback (most recent call last):\n",
      "  File \"C:\\users\\Milner\\anaconda3\\envs\\trailmap_env\\lib\\site-packages\\IPython\\core\\interactiveshell.py\", line 3377, in run_ast_nodes\n",
      "    if (await self.run_code(code, result,  async_=asy)):\n",
      "  File \"C:\\users\\Milner\\anaconda3\\envs\\trailmap_env\\lib\\site-packages\\IPython\\core\\interactiveshell.py\", line 3474, in run_code\n",
      "    self.showtraceback(running_compiled_code=True)\n",
      "  File \"C:\\users\\Milner\\anaconda3\\envs\\trailmap_env\\lib\\site-packages\\IPython\\core\\interactiveshell.py\", line 2080, in showtraceback\n",
      "    value, tb, tb_offset=tb_offset)\n",
      "  File \"C:\\users\\Milner\\anaconda3\\envs\\trailmap_env\\lib\\site-packages\\IPython\\core\\ultratb.py\", line 1368, in structured_traceback\n",
      "    self, etype, value, tb, tb_offset, number_of_lines_of_context)\n",
      "  File \"C:\\users\\Milner\\anaconda3\\envs\\trailmap_env\\lib\\site-packages\\IPython\\core\\ultratb.py\", line 1268, in structured_traceback\n",
      "    self, etype, value, tb, tb_offset, number_of_lines_of_context\n",
      "  File \"C:\\users\\Milner\\anaconda3\\envs\\trailmap_env\\lib\\site-packages\\IPython\\core\\ultratb.py\", line 1125, in structured_traceback\n",
      "    tb_offset)\n",
      "  File \"C:\\users\\Milner\\anaconda3\\envs\\trailmap_env\\lib\\site-packages\\IPython\\core\\ultratb.py\", line 1082, in format_exception_as_a_whole\n",
      "    last_unique, recursion_repeat = find_recursion(orig_etype, evalue, records)\n",
      "  File \"C:\\users\\Milner\\anaconda3\\envs\\trailmap_env\\lib\\site-packages\\IPython\\core\\ultratb.py\", line 382, in find_recursion\n",
      "    return len(records), 0\n",
      "TypeError: object of type 'NoneType' has no len()\n",
      "\n",
      "During handling of the above exception, another exception occurred:\n",
      "\n",
      "Traceback (most recent call last):\n",
      "  File \"C:\\users\\Milner\\anaconda3\\envs\\trailmap_env\\lib\\site-packages\\IPython\\core\\interactiveshell.py\", line 2077, in showtraceback\n",
      "    stb = value._render_traceback_()\n",
      "AttributeError: 'TypeError' object has no attribute '_render_traceback_'\n",
      "\n",
      "During handling of the above exception, another exception occurred:\n",
      "\n",
      "Traceback (most recent call last):\n",
      "  File \"C:\\users\\Milner\\anaconda3\\envs\\trailmap_env\\lib\\site-packages\\IPython\\core\\ultratb.py\", line 1101, in get_records\n",
      "    return _fixed_getinnerframes(etb, number_of_lines_of_context, tb_offset)\n",
      "  File \"C:\\users\\Milner\\anaconda3\\envs\\trailmap_env\\lib\\site-packages\\IPython\\core\\ultratb.py\", line 248, in wrapped\n",
      "    return f(*args, **kwargs)\n",
      "  File \"C:\\users\\Milner\\anaconda3\\envs\\trailmap_env\\lib\\site-packages\\IPython\\core\\ultratb.py\", line 281, in _fixed_getinnerframes\n",
      "    records = fix_frame_records_filenames(inspect.getinnerframes(etb, context))\n",
      "  File \"C:\\users\\Milner\\anaconda3\\envs\\trailmap_env\\lib\\inspect.py\", line 1502, in getinnerframes\n",
      "    frameinfo = (tb.tb_frame,) + getframeinfo(tb, context)\n",
      "  File \"C:\\users\\Milner\\anaconda3\\envs\\trailmap_env\\lib\\inspect.py\", line 1460, in getframeinfo\n",
      "    filename = getsourcefile(frame) or getfile(frame)\n",
      "  File \"C:\\users\\Milner\\anaconda3\\envs\\trailmap_env\\lib\\inspect.py\", line 696, in getsourcefile\n",
      "    if getattr(getmodule(object, filename), '__loader__', None) is not None:\n",
      "  File \"C:\\users\\Milner\\anaconda3\\envs\\trailmap_env\\lib\\inspect.py\", line 733, in getmodule\n",
      "    if ismodule(module) and hasattr(module, '__file__'):\n",
      "  File \"C:\\users\\Milner\\anaconda3\\envs\\trailmap_env\\lib\\site-packages\\tensorflow\\__init__.py\", line 50, in __getattr__\n",
      "    module = self._load()\n",
      "  File \"C:\\users\\Milner\\anaconda3\\envs\\trailmap_env\\lib\\site-packages\\tensorflow\\__init__.py\", line 44, in _load\n",
      "    module = _importlib.import_module(self.__name__)\n",
      "  File \"C:\\users\\Milner\\anaconda3\\envs\\trailmap_env\\lib\\importlib\\__init__.py\", line 127, in import_module\n",
      "    return _bootstrap._gcd_import(name[level:], package, level)\n",
      "  File \"<frozen importlib._bootstrap>\", line 1006, in _gcd_import\n",
      "  File \"<frozen importlib._bootstrap>\", line 983, in _find_and_load\n",
      "  File \"<frozen importlib._bootstrap>\", line 965, in _find_and_load_unlocked\n",
      "ModuleNotFoundError: No module named 'tensorflow_core.estimator'\n",
      "Traceback (most recent call last):\n",
      "  File \"C:\\users\\Milner\\anaconda3\\envs\\trailmap_env\\lib\\site-packages\\IPython\\core\\interactiveshell.py\", line 3457, in run_code\n",
      "    exec(code_obj, self.user_global_ns, self.user_ns)\n",
      "  File \"C:\\Users\\Milner\\AppData\\Local\\Temp\\ipykernel_16592\\3907816014.py\", line 5, in <module>\n",
      "    import pylab as plt\n",
      "ModuleNotFoundError: No module named 'pylab'\n",
      "\n",
      "During handling of the above exception, another exception occurred:\n",
      "\n",
      "Traceback (most recent call last):\n",
      "  File \"C:\\users\\Milner\\anaconda3\\envs\\trailmap_env\\lib\\site-packages\\IPython\\core\\interactiveshell.py\", line 2077, in showtraceback\n",
      "    stb = value._render_traceback_()\n",
      "AttributeError: 'ModuleNotFoundError' object has no attribute '_render_traceback_'\n",
      "\n",
      "During handling of the above exception, another exception occurred:\n",
      "\n",
      "Traceback (most recent call last):\n",
      "  File \"C:\\users\\Milner\\anaconda3\\envs\\trailmap_env\\lib\\site-packages\\IPython\\core\\interactiveshell.py\", line 3377, in run_ast_nodes\n",
      "    if (await self.run_code(code, result,  async_=asy)):\n",
      "  File \"C:\\users\\Milner\\anaconda3\\envs\\trailmap_env\\lib\\site-packages\\IPython\\core\\interactiveshell.py\", line 3474, in run_code\n",
      "    self.showtraceback(running_compiled_code=True)\n",
      "  File \"C:\\users\\Milner\\anaconda3\\envs\\trailmap_env\\lib\\site-packages\\IPython\\core\\interactiveshell.py\", line 2080, in showtraceback\n",
      "    value, tb, tb_offset=tb_offset)\n",
      "  File \"C:\\users\\Milner\\anaconda3\\envs\\trailmap_env\\lib\\site-packages\\IPython\\core\\ultratb.py\", line 1368, in structured_traceback\n",
      "    self, etype, value, tb, tb_offset, number_of_lines_of_context)\n",
      "  File \"C:\\users\\Milner\\anaconda3\\envs\\trailmap_env\\lib\\site-packages\\IPython\\core\\ultratb.py\", line 1268, in structured_traceback\n",
      "    self, etype, value, tb, tb_offset, number_of_lines_of_context\n",
      "  File \"C:\\users\\Milner\\anaconda3\\envs\\trailmap_env\\lib\\site-packages\\IPython\\core\\ultratb.py\", line 1125, in structured_traceback\n",
      "    tb_offset)\n",
      "  File \"C:\\users\\Milner\\anaconda3\\envs\\trailmap_env\\lib\\site-packages\\IPython\\core\\ultratb.py\", line 1082, in format_exception_as_a_whole\n",
      "    last_unique, recursion_repeat = find_recursion(orig_etype, evalue, records)\n",
      "  File \"C:\\users\\Milner\\anaconda3\\envs\\trailmap_env\\lib\\site-packages\\IPython\\core\\ultratb.py\", line 382, in find_recursion\n",
      "    return len(records), 0\n",
      "TypeError: object of type 'NoneType' has no len()\n",
      "\n",
      "During handling of the above exception, another exception occurred:\n",
      "\n",
      "Traceback (most recent call last):\n",
      "  File \"C:\\users\\Milner\\anaconda3\\envs\\trailmap_env\\lib\\site-packages\\IPython\\core\\interactiveshell.py\", line 2077, in showtraceback\n",
      "    stb = value._render_traceback_()\n",
      "AttributeError: 'TypeError' object has no attribute '_render_traceback_'\n",
      "\n",
      "During handling of the above exception, another exception occurred:\n",
      "\n",
      "Traceback (most recent call last):\n",
      "  File \"C:\\users\\Milner\\anaconda3\\envs\\trailmap_env\\lib\\site-packages\\IPython\\core\\interactiveshell.py\", line 2960, in _run_cell\n",
      "    return runner(coro)\n",
      "  File \"C:\\users\\Milner\\anaconda3\\envs\\trailmap_env\\lib\\site-packages\\IPython\\core\\async_helpers.py\", line 78, in _pseudo_sync_runner\n",
      "    coro.send(None)\n",
      "  File \"C:\\users\\Milner\\anaconda3\\envs\\trailmap_env\\lib\\site-packages\\IPython\\core\\interactiveshell.py\", line 3186, in run_cell_async\n",
      "    interactivity=interactivity, compiler=compiler, result=result)\n",
      "  File \"C:\\users\\Milner\\anaconda3\\envs\\trailmap_env\\lib\\site-packages\\IPython\\core\\interactiveshell.py\", line 3396, in run_ast_nodes\n",
      "    self.showtraceback()\n",
      "  File \"C:\\users\\Milner\\anaconda3\\envs\\trailmap_env\\lib\\site-packages\\IPython\\core\\interactiveshell.py\", line 2080, in showtraceback\n",
      "    value, tb, tb_offset=tb_offset)\n",
      "  File \"C:\\users\\Milner\\anaconda3\\envs\\trailmap_env\\lib\\site-packages\\IPython\\core\\ultratb.py\", line 1368, in structured_traceback\n",
      "    self, etype, value, tb, tb_offset, number_of_lines_of_context)\n",
      "  File \"C:\\users\\Milner\\anaconda3\\envs\\trailmap_env\\lib\\site-packages\\IPython\\core\\ultratb.py\", line 1268, in structured_traceback\n",
      "    self, etype, value, tb, tb_offset, number_of_lines_of_context\n",
      "  File \"C:\\users\\Milner\\anaconda3\\envs\\trailmap_env\\lib\\site-packages\\IPython\\core\\ultratb.py\", line 1143, in structured_traceback\n",
      "    chained_exceptions_tb_offset)\n",
      "  File \"C:\\users\\Milner\\anaconda3\\envs\\trailmap_env\\lib\\site-packages\\IPython\\core\\ultratb.py\", line 1082, in format_exception_as_a_whole\n",
      "    last_unique, recursion_repeat = find_recursion(orig_etype, evalue, records)\n",
      "  File \"C:\\users\\Milner\\anaconda3\\envs\\trailmap_env\\lib\\site-packages\\IPython\\core\\ultratb.py\", line 382, in find_recursion\n",
      "    return len(records), 0\n",
      "TypeError: object of type 'NoneType' has no len()\n",
      "\n",
      "During handling of the above exception, another exception occurred:\n",
      "\n",
      "Traceback (most recent call last):\n",
      "  File \"C:\\users\\Milner\\anaconda3\\envs\\trailmap_env\\lib\\site-packages\\IPython\\core\\interactiveshell.py\", line 2077, in showtraceback\n",
      "    stb = value._render_traceback_()\n",
      "AttributeError: 'TypeError' object has no attribute '_render_traceback_'\n",
      "\n",
      "During handling of the above exception, another exception occurred:\n",
      "\n",
      "Traceback (most recent call last):\n",
      "  File \"C:\\users\\Milner\\anaconda3\\envs\\trailmap_env\\lib\\site-packages\\IPython\\core\\ultratb.py\", line 1101, in get_records\n",
      "    return _fixed_getinnerframes(etb, number_of_lines_of_context, tb_offset)\n",
      "  File \"C:\\users\\Milner\\anaconda3\\envs\\trailmap_env\\lib\\site-packages\\IPython\\core\\ultratb.py\", line 248, in wrapped\n",
      "    return f(*args, **kwargs)\n",
      "  File \"C:\\users\\Milner\\anaconda3\\envs\\trailmap_env\\lib\\site-packages\\IPython\\core\\ultratb.py\", line 281, in _fixed_getinnerframes\n",
      "    records = fix_frame_records_filenames(inspect.getinnerframes(etb, context))\n",
      "  File \"C:\\users\\Milner\\anaconda3\\envs\\trailmap_env\\lib\\inspect.py\", line 1502, in getinnerframes\n",
      "    frameinfo = (tb.tb_frame,) + getframeinfo(tb, context)\n",
      "  File \"C:\\users\\Milner\\anaconda3\\envs\\trailmap_env\\lib\\inspect.py\", line 1460, in getframeinfo\n",
      "    filename = getsourcefile(frame) or getfile(frame)\n",
      "  File \"C:\\users\\Milner\\anaconda3\\envs\\trailmap_env\\lib\\inspect.py\", line 696, in getsourcefile\n",
      "    if getattr(getmodule(object, filename), '__loader__', None) is not None:\n",
      "  File \"C:\\users\\Milner\\anaconda3\\envs\\trailmap_env\\lib\\inspect.py\", line 733, in getmodule\n",
      "    if ismodule(module) and hasattr(module, '__file__'):\n",
      "  File \"C:\\users\\Milner\\anaconda3\\envs\\trailmap_env\\lib\\site-packages\\tensorflow\\__init__.py\", line 50, in __getattr__\n",
      "    module = self._load()\n",
      "  File \"C:\\users\\Milner\\anaconda3\\envs\\trailmap_env\\lib\\site-packages\\tensorflow\\__init__.py\", line 44, in _load\n",
      "    module = _importlib.import_module(self.__name__)\n",
      "  File \"C:\\users\\Milner\\anaconda3\\envs\\trailmap_env\\lib\\importlib\\__init__.py\", line 127, in import_module\n",
      "    return _bootstrap._gcd_import(name[level:], package, level)\n",
      "  File \"<frozen importlib._bootstrap>\", line 1006, in _gcd_import\n",
      "  File \"<frozen importlib._bootstrap>\", line 983, in _find_and_load\n",
      "  File \"<frozen importlib._bootstrap>\", line 965, in _find_and_load_unlocked\n",
      "ModuleNotFoundError: No module named 'tensorflow_core.estimator'\n"
     ]
    }
   ],
   "source": [
    "import numpy as np\n",
    "dd = np.stack(stack.downsampled_data)\n",
    "rgb = dd.transpose([1,2,3,0])\n",
    "\n",
    "import pylab as plt"
   ]
  }
 ],
 "metadata": {
  "kernelspec": {
   "display_name": "Python 3 (ipykernel)",
   "language": "python",
   "name": "python3"
  },
  "language_info": {
   "codemirror_mode": {
    "name": "ipython",
    "version": 3
   },
   "file_extension": ".py",
   "mimetype": "text/x-python",
   "name": "python",
   "nbconvert_exporter": "python",
   "pygments_lexer": "ipython3",
   "version": "3.7.11"
  }
 },
 "nbformat": 4,
 "nbformat_minor": 5
}
